Bot control script started at Sat Sep 14 00:30:33 CEST 2024
PID file not found at Sat Sep 14 00:30:33 CEST 2024
Starting bot and generating figures at Sat Sep 14 00:30:33 CEST 2024
Dataframe is empty -> no uploads for yesterday
Bot started with PID 97428 at Sat Sep 14 00:30:34 CEST 2024
Updates were skipped successfully.
Cause exception while getting updates.
Traceback (most recent call last):
  File "/Users/ivanivsnov/dev/Polish-IT-Jobs-Aggregator/venv/lib/python3.11/site-packages/aiogram/dispatcher/dispatcher.py", line 381, in start_polling
    updates = await self.bot.get_updates(
              ^^^^^^^^^^^^^^^^^^^^^^^^^^^
  File "/Users/ivanivsnov/dev/Polish-IT-Jobs-Aggregator/venv/lib/python3.11/site-packages/aiogram/bot/bot.py", line 110, in get_updates
    result = await self.request(api.Methods.GET_UPDATES, payload)
             ^^^^^^^^^^^^^^^^^^^^^^^^^^^^^^^^^^^^^^^^^^^^^^^^^^^^
  File "/Users/ivanivsnov/dev/Polish-IT-Jobs-Aggregator/venv/lib/python3.11/site-packages/aiogram/bot/base.py", line 231, in request
    return await api.make_request(await self.get_session(), self.server, self.__token, method, data, files,
           ^^^^^^^^^^^^^^^^^^^^^^^^^^^^^^^^^^^^^^^^^^^^^^^^^^^^^^^^^^^^^^^^^^^^^^^^^^^^^^^^^^^^^^^^^^^^^^^^
  File "/Users/ivanivsnov/dev/Polish-IT-Jobs-Aggregator/venv/lib/python3.11/site-packages/aiogram/bot/api.py", line 140, in make_request
    return check_result(method, response.content_type, response.status, await response.text())
           ^^^^^^^^^^^^^^^^^^^^^^^^^^^^^^^^^^^^^^^^^^^^^^^^^^^^^^^^^^^^^^^^^^^^^^^^^^^^^^^^^^^
  File "/Users/ivanivsnov/dev/Polish-IT-Jobs-Aggregator/venv/lib/python3.11/site-packages/aiogram/bot/api.py", line 119, in check_result
    exceptions.ConflictError.detect(description)
  File "/Users/ivanivsnov/dev/Polish-IT-Jobs-Aggregator/venv/lib/python3.11/site-packages/aiogram/utils/exceptions.py", line 140, in detect
    raise err(cls.text or description)
aiogram.utils.exceptions.TerminatedByOtherGetUpdates: Terminated by other getupdates request; make sure that only one bot instance is running
Cause exception while getting updates.
Traceback (most recent call last):
  File "/Users/ivanivsnov/dev/Polish-IT-Jobs-Aggregator/venv/lib/python3.11/site-packages/aiogram/dispatcher/dispatcher.py", line 381, in start_polling
    updates = await self.bot.get_updates(
              ^^^^^^^^^^^^^^^^^^^^^^^^^^^
  File "/Users/ivanivsnov/dev/Polish-IT-Jobs-Aggregator/venv/lib/python3.11/site-packages/aiogram/bot/bot.py", line 110, in get_updates
    result = await self.request(api.Methods.GET_UPDATES, payload)
             ^^^^^^^^^^^^^^^^^^^^^^^^^^^^^^^^^^^^^^^^^^^^^^^^^^^^
  File "/Users/ivanivsnov/dev/Polish-IT-Jobs-Aggregator/venv/lib/python3.11/site-packages/aiogram/bot/base.py", line 231, in request
    return await api.make_request(await self.get_session(), self.server, self.__token, method, data, files,
           ^^^^^^^^^^^^^^^^^^^^^^^^^^^^^^^^^^^^^^^^^^^^^^^^^^^^^^^^^^^^^^^^^^^^^^^^^^^^^^^^^^^^^^^^^^^^^^^^
  File "/Users/ivanivsnov/dev/Polish-IT-Jobs-Aggregator/venv/lib/python3.11/site-packages/aiogram/bot/api.py", line 140, in make_request
    return check_result(method, response.content_type, response.status, await response.text())
           ^^^^^^^^^^^^^^^^^^^^^^^^^^^^^^^^^^^^^^^^^^^^^^^^^^^^^^^^^^^^^^^^^^^^^^^^^^^^^^^^^^^
  File "/Users/ivanivsnov/dev/Polish-IT-Jobs-Aggregator/venv/lib/python3.11/site-packages/aiogram/bot/api.py", line 119, in check_result
    exceptions.ConflictError.detect(description)
  File "/Users/ivanivsnov/dev/Polish-IT-Jobs-Aggregator/venv/lib/python3.11/site-packages/aiogram/utils/exceptions.py", line 140, in detect
    raise err(cls.text or description)
aiogram.utils.exceptions.TerminatedByOtherGetUpdates: Terminated by other getupdates request; make sure that only one bot instance is running
Cause exception while getting updates.
Traceback (most recent call last):
  File "/Users/ivanivsnov/dev/Polish-IT-Jobs-Aggregator/venv/lib/python3.11/site-packages/aiogram/dispatcher/dispatcher.py", line 381, in start_polling
    updates = await self.bot.get_updates(
              ^^^^^^^^^^^^^^^^^^^^^^^^^^^
  File "/Users/ivanivsnov/dev/Polish-IT-Jobs-Aggregator/venv/lib/python3.11/site-packages/aiogram/bot/bot.py", line 110, in get_updates
    result = await self.request(api.Methods.GET_UPDATES, payload)
             ^^^^^^^^^^^^^^^^^^^^^^^^^^^^^^^^^^^^^^^^^^^^^^^^^^^^
  File "/Users/ivanivsnov/dev/Polish-IT-Jobs-Aggregator/venv/lib/python3.11/site-packages/aiogram/bot/base.py", line 231, in request
    return await api.make_request(await self.get_session(), self.server, self.__token, method, data, files,
           ^^^^^^^^^^^^^^^^^^^^^^^^^^^^^^^^^^^^^^^^^^^^^^^^^^^^^^^^^^^^^^^^^^^^^^^^^^^^^^^^^^^^^^^^^^^^^^^^
  File "/Users/ivanivsnov/dev/Polish-IT-Jobs-Aggregator/venv/lib/python3.11/site-packages/aiogram/bot/api.py", line 140, in make_request
    return check_result(method, response.content_type, response.status, await response.text())
           ^^^^^^^^^^^^^^^^^^^^^^^^^^^^^^^^^^^^^^^^^^^^^^^^^^^^^^^^^^^^^^^^^^^^^^^^^^^^^^^^^^^
  File "/Users/ivanivsnov/dev/Polish-IT-Jobs-Aggregator/venv/lib/python3.11/site-packages/aiogram/bot/api.py", line 119, in check_result
    exceptions.ConflictError.detect(description)
  File "/Users/ivanivsnov/dev/Polish-IT-Jobs-Aggregator/venv/lib/python3.11/site-packages/aiogram/utils/exceptions.py", line 140, in detect
    raise err(cls.text or description)
aiogram.utils.exceptions.TerminatedByOtherGetUpdates: Terminated by other getupdates request; make sure that only one bot instance is running
Goodbye!
--------------------------------------
 Bot has started
Bot startup completed and notification check loop started.
Signal received, saving user data and exiting...
Exiting...
Stopping bot with PID 97428 at Sat Sep 14 00:31:01 CEST 2024
Bot stopped at Sat Sep 14 00:31:01 CEST 2024
Sending bot logs via email at Sat Sep 14 00:31:01 CEST 2024

----------------------------------------
Seding email to makararena@gmail.com

----------------------------------------
Email with bot logs sent at Sat Sep 14 00:31:03 CEST 2024
PID file not found at Sat Sep 14 00:31:03 CEST 2024
Sending bot logs via email at Sat Sep 14 00:31:03 CEST 2024

----------------------------------------
Seding email to makararena@gmail.com

----------------------------------------
Email with bot logs sent at Sat Sep 14 00:31:05 CEST 2024
